<mujoco model="hi_12dof">
  <compiler angle="radian" meshdir="meshes/"/>
  <statistic meansize="0.144785" extent="1.23314" center="0.025392 2.0634e-05 -0.245975"/>
  <default>
    <joint damping="0.001" armature="0.01" frictionloss="0.08"/>
  </default>

  <asset>
    <mesh name="base_link" file="base_link.STL"/>
    <mesh name="l_hip_pitch_link" file="l_hip_pitch_link.STL"/>
    <mesh name="l_hip_roll_link" file="l_hip_roll_link.STL"/>
    <mesh name="l_hip_thigh_link" file="l_hip_thigh_link.STL"/>
    <mesh name="l_hip_calf_link" file="l_hip_calf_link.STL"/>
    <mesh name="l_ankle_pitch_link" file="l_ankle_pitch_link.STL"/>
    <mesh name="l_ankle_roll_link" file="l_ankle_roll_link.STL"/>
    <mesh name="ankle_roll_simplify" file="ankle_roll_simplify.STL" scale="0.001 0.001 0.001"/>
    <mesh name="r_hip_pitch_link" file="r_hip_pitch_link.STL"/>
    <mesh name="r_hip_roll_link" file="r_hip_roll_link.STL"/>
    <mesh name="r_hip_thigh_link" file="r_hip_thigh_link.STL"/>
    <mesh name="r_hip_calf_link" file="r_hip_calf_link.STL"/>
    <mesh name="r_ankle_pitch_link" file="r_ankle_pitch_link.STL"/>
    <mesh name="r_ankle_roll_link" file="r_ankle_roll_link.STL"/>
    <mesh name="waist_yaw_link" file="waist_yaw_link.STL"/>
    <mesh name="l_shoulder_pitch_link" file="l_shoulder_pitch_link.STL"/>
    <mesh name="l_shoulder_roll_link" file="l_shoulder_roll_link.STL"/>
    <mesh name="l_upper_arm_link" file="l_upper_arm_link.STL"/>
    <mesh name="l_elbow_link" file="l_elbow_link.STL"/>
    <mesh name="l_wrist_link" file="l_wrist_link.STL"/>
    <mesh name="r_shoulder_pitch_link" file="r_shoulder_pitch_link.STL"/>
    <mesh name="r_shoulder_roll_link" file="r_shoulder_roll_link.STL"/>
    <mesh name="r_upper_arm_link" file="r_upper_arm_link.STL"/>
    <mesh name="r_elbow_link" file="r_elbow_link.STL"/>
    <mesh name="r_wrist_link" file="r_wrist_link.STL"/>
    <mesh name="head_yaw_link" file="head_yaw_link.STL"/>
    <mesh name="head_pitch_link" file="head_pitch_link.STL"/>
  </asset>

  <worldbody>
    <body name="base_link" pos="0 0 0.45">
      <inertial pos="-0.00501504 -0.0239609 0.11686" quat="0.394114 0.911959 0.113941 -0.00475485" mass="10.3302" diaginertia="0.226368 0.193179 0.123846"/>
      <joint name="floating_base_joint" type="free"/>
      <geom type="mesh" contype="0" conaffinity="0" group="1" density="0" rgba="0.89804 0.91765 0.92941 1" mesh="base_link"/>
      <geom size="0.025 0.05 0.0325" pos="0 0 -0.04" type="box" rgba="0.89804 0.91765 0.92941 1"/>
      <geom pos="0 0 0.028" type="mesh" contype="0" conaffinity="0" group="1" density="0" rgba="0.89804 0.91765 0.92941 1" mesh="waist_yaw_link"/>
      <geom size="0.045 0.035 0.025" pos="0 0 0.028" type="box" rgba="0.89804 0.91765 0.92941 1"/>
      <geom size="0.06 0.1 0.105" pos="0 0 0.168" type="box" rgba="0.89804 0.91765 0.92941 1"/>
      <geom pos="0 0.0958 0.233" quat="1 0 0 0" type="mesh" contype="0" conaffinity="0" group="1" density="0" rgba="0.89804 0.91765 0.92941 1" mesh="l_shoulder_pitch_link"/>
      <geom size="0.025 0.03 0.025" pos="0 0.1488 0.233" type="box" rgba="0.89804 0.91765 0.92941 1"/>
      <geom pos="0 0.15355 0.233" quat="1 0 0 0" type="mesh" contype="0" conaffinity="0" group="1" density="0" rgba="0.79216 0.81961 0.93333 1" mesh="l_shoulder_roll_link"/>
      <geom size="0.025 0.025 0.025" pos="0 0.15355 0.163" type="box" rgba="0.79216 0.81961 0.93333 1"/>
      <geom pos="0 0.1533 0.16165" quat="1 0 0 0" type="mesh" contype="0" conaffinity="0" group="1" density="0" rgba="0.89804 0.91765 0.92941 1" mesh="l_upper_arm_link"/>
      <geom size="0.025 0.025 0.025" pos="0 0.1533 0.10165" type="box" rgba="0.89804 0.91765 0.92941 1"/>
      <geom pos="0 0.1533 0.1013" type="mesh" contype="0" conaffinity="0" group="1" density="0" rgba="0.79216 0.81961 0.93333 1" mesh="l_elbow_link"/>
      <geom size="0.02 0.02 0.02" pos="0 0.1533 0.0363" type="box" rgba="0.79216 0.81961 0.93333 1"/>
      <geom pos="0 0.1533 0.0346" type="mesh" contype="0" conaffinity="0" group="1" density="0" rgba="0.89804 0.91765 0.92941 1" mesh="l_wrist_link"/>
      <geom size="0.01 0.01 0.0125" pos="0 0.1533 -0.0084" type="box" rgba="0.89804 0.91765 0.92941 1"/>
      <geom name="end_collision" size="0.0175" pos="0 0.1533 -0.0374" rgba="0.89804 0.91765 0.92941 1"/>
      <geom pos="0 -0.0958 0.233" quat="1 0 0 0" type="mesh" contype="0" conaffinity="0" group="1" density="0" rgba="0.89804 0.91765 0.92941 1" mesh="r_shoulder_pitch_link"/>
      <geom size="0.025 0.03 0.025" pos="0 -0.1488 0.233" type="box" rgba="0.89804 0.91765 0.92941 1"/>
      <geom pos="0 -0.15355 0.233" quat="1 0 0 0" type="mesh" contype="0" conaffinity="0" group="1" density="0" rgba="0.79216 0.81961 0.93333 1" mesh="r_shoulder_roll_link"/>
      <geom size="0.025 0.025 0.025" pos="0 -0.15355 0.163" type="box" rgba="0.79216 0.81961 0.93333 1"/>
      <geom pos="0 -0.1533 0.16165" quat="1 0 0 0" type="mesh" contype="0" conaffinity="0" group="1" density="0" rgba="0.89804 0.91765 0.92941 1" mesh="r_upper_arm_link"/>
      <geom size="0.025 0.025 0.025" pos="0 -0.1533 0.10165" type="box" rgba="0.89804 0.91765 0.92941 1"/>
      <geom pos="0 -0.1533 0.1013" type="mesh" contype="0" conaffinity="0" group="1" density="0" rgba="0.79216 0.81961 0.93333 1" mesh="r_elbow_link"/>
      <geom size="0.02 0.02 0.02" pos="0 -0.1533 0.0363" type="box" rgba="0.79216 0.81961 0.93333 1"/>
      <geom pos="0 -0.1533 0.0346" type="mesh" contype="0" conaffinity="0" group="1" density="0" rgba="0.89804 0.91765 0.92941 1" mesh="r_wrist_link"/>
      <geom size="0.01 0.01 0.0125" pos="0 -0.1533 -0.0084" type="box" rgba="0.89804 0.91765 0.92941 1"/>
      <geom size="0.0175" pos="0 -0.1533 -0.0374" rgba="0.89804 0.91765 0.92941 1"/>
      <geom pos="0 0 0.31205" type="mesh" contype="0" conaffinity="0" group="1" density="0" rgba="0.89804 0.91765 0.92941 1" mesh="head_yaw_link"/>
      <geom size="0.015 0.015 0.015" pos="0 0 0.29705" type="box" rgba="0.89804 0.91765 0.92941 1"/>
      <geom pos="0 0.0015 0.3556" quat="1 0 0 0" type="mesh" contype="0" conaffinity="0" group="1" density="0" rgba="0.89804 0.91765 0.92941 1" mesh="head_pitch_link"/>
      <geom size="0.05 0.075 0.015" pos="0 0.0015 0.3806" type="box" rgba="0.89804 0.91765 0.92941 1"/>
      <body name="l_hip_pitch_link" pos="0 0.0295 -0.04">
        <inertial pos="0.0003884 0.067835 8.28e-05" quat="0.556493 0.438278 -0.560847 0.428578" mass="0.66505" diaginertia="0.000223908 0.000192604 0.000189288"/>
        <joint name="l_hip_pitch_joint" pos="0 0 0" axis="0 1 0" range="-3.0369 3.0369" actuatorfrcrange="-32.4 32.4"/>
        <geom type="mesh" contype="0" conaffinity="0" group="1" density="0" rgba="0.89804 0.91765 0.92941 1" mesh="l_hip_pitch_link"/>
        <geom size="0.03 0.035 0.03" pos="0 0.065 0" type="box" rgba="0.89804 0.91765 0.92941 1"/>
        <body name="l_hip_roll_link" pos="0 0.07 0">
          <inertial pos="0.0009598 0.0001312 -0.081116" quat="0.70836 0.0236484 0.0227625 0.705088" mass="0.78331" diaginertia="0.00146241 0.00126332 0.000491778"/>
          <joint name="l_hip_roll_joint" pos="0 0 0" axis="1 0 0" range="-0.45379 2.618" actuatorfrcrange="-32.4 32.4"/>
          <geom type="mesh" contype="0" conaffinity="0" group="1" density="0" rgba="0.79216 0.81961 0.93333 1" mesh="l_hip_roll_link"/>
          <geom size="0.03 0.035 0.03" pos="0 0 -0.09" type="box" rgba="0.79216 0.81961 0.93333 1"/>
          <body name="l_hip_thigh_link" pos="0 0 -0.095">
            <inertial pos="0 -0.00080909 -0.059296" quat="0.588254 0.808676 0 0" mass="0.24756" diaginertia="0.0003962 0.000271392 0.000245108"/>
            <joint name="l_hip_thigh_joint" pos="0 0 0" axis="0 0 1" range="-0.7854 0.7854" actuatorfrcrange="-32.4 32.4"/>
            <geom type="mesh" contype="0" conaffinity="0" group="1" density="0" rgba="0.89804 0.91765 0.92941 1" mesh="l_hip_thigh_link"/>
            <geom size="0.005 0.005 0.005" pos="0 0 -0.005" type="box" rgba="0.89804 0.91765 0.92941 1"/>
            <body name="l_hip_calf_link" pos="0 0.00375 -0.097">
              <inertial pos="0.0010123 -0.0024674 -0.064494" quat="0.749749 -0.0135581 0.00418962 0.66157" mass="1.6427" diaginertia="0.00606559 0.00600124 0.000543567"/>
              <joint name="l_hip_calf_joint" pos="0 0 0" axis="0 1 0" range="-1.5708 2.0944" actuatorfrcrange="-32.4 32.4"/>
              <geom type="mesh" contype="0" conaffinity="0" group="1" density="0" rgba="0.89804 0.91765 0.92941 1" mesh="l_hip_calf_link"/>
              <geom size="0.03 0.03 0.105" pos="0 0 -0.06" type="box" rgba="0.89804 0.91765 0.92941 1"/>
              <body name="l_ankle_pitch_link" pos="0 -0.00375 -0.19945">
                <inertial pos="0 0 0" quat="0.5 0.5 -0.5 0.5" mass="0.056538" diaginertia="6.3e-06 4.9e-06 4.7e-06"/>
                <joint name="l_ankle_pitch_joint" pos="0 0 0" axis="0 1 0" range="-0.90757 0.7854" actuatorfrcrange="-14.4 14.4"/>
                <geom type="mesh" contype="0" conaffinity="0" group="1" density="0" rgba="0.89804 0.91765 0.92941 1" mesh="l_ankle_pitch_link"/>
                <geom size="0.005 0.005 0.005" type="box" rgba="0.89804 0.91765 0.92941 1"/>
                <body name="l_ankle_roll_link">
                  <inertial pos="0.017291 0.00079987 -0.030752" quat="-0.0717589 0.724448 -0.0777767 0.681158" mass="0.59911" diaginertia="0.00144003 0.00137984 0.000239531"/>
                  <joint name="l_ankle_roll_joint" pos="0 0 0" axis="1 0 0" range="-0.37525 0.37525" actuatorfrcrange="-14.4 14.4"/>
                  <geom type="mesh" contype="0" conaffinity="0" group="1" density="0" rgba="0.89804 0.91765 0.92941 1" mesh="l_ankle_roll_link"/>
                  <geom pos="-0.067 0.033 -0.044" quat="0.707388 0 0 -0.706825" type="mesh" rgba="0.89804 0.91765 0.92941 1" mesh="ankle_roll_simplify"/>
                </body>
              </body>
            </body>
          </body>
        </body>
      </body>
      <body name="r_hip_pitch_link" pos="0 -0.0295 -0.04">
        <inertial pos="0.0003884 -0.067835 -8.28e-05" quat="0.428578 0.560847 -0.438278 0.556493" mass="0.66505" diaginertia="0.000223908 0.000192604 0.000189288"/>
        <joint name="r_hip_pitch_joint" pos="0 0 0" axis="0 1 0" range="-3.0369 3.0369" actuatorfrcrange="-32.4 32.4"/>
        <geom type="mesh" contype="0" conaffinity="0" group="1" density="0" rgba="0.89804 0.91765 0.92941 1" mesh="r_hip_pitch_link"/>
        <geom size="0.03 0.035 0.03" pos="0 -0.065 0" type="box" rgba="0.89804 0.91765 0.92941 1"/>
        <body name="r_hip_roll_link" pos="0 -0.07 0">
          <inertial pos="0.0009598 -0.0001312 -0.081116" quat="0.708631 0.0226903 0.0237133 0.704816" mass="0.78331" diaginertia="0.00146241 0.00126331 0.000491779"/>
          <joint name="r_hip_roll_joint" pos="0 0 0" axis="1 0 0" range="-2.618 0.45379" actuatorfrcrange="-32.4 32.4"/>
          <geom type="mesh" contype="0" conaffinity="0" group="1" density="0" rgba="0.79216 0.81961 0.93333 1" mesh="r_hip_roll_link"/>
          <geom size="0.03 0.035 0.03" pos="0 0 -0.09" type="box" rgba="0.79216 0.81961 0.93333 1"/>
          <body name="r_hip_thigh_link" pos="0 0 -0.095">
            <inertial pos="0 0.00080909 -0.059296" quat="0.808676 0.588254 0 0" mass="0.24756" diaginertia="0.0003962 0.000271392 0.000245108"/>
            <joint name="r_hip_thigh_joint" pos="0 0 0" axis="0 0 1" range="-0.7854 0.7854" actuatorfrcrange="-32.4 32.4"/>
            <geom type="mesh" contype="0" conaffinity="0" group="1" density="0" rgba="0.89804 0.91765 0.92941 1" mesh="r_hip_thigh_link"/>
            <geom size="0.005 0.005 0.005" pos="0 0 -0.005" type="box" rgba="0.89804 0.91765 0.92941 1"/>
            <body name="r_hip_calf_link" pos="0 -0.00375 -0.097">
              <inertial pos="0.0010123 0.0024674 -0.064494" quat="0.66157 0.00418962 -0.0135581 0.749749" mass="1.6427" diaginertia="0.00606559 0.00600124 0.000543567"/>
              <joint name="r_hip_calf_joint" pos="0 0 0" axis="0 1 0" range="-1.5708 2.0944" actuatorfrcrange="-32.4 32.4"/>
              <geom type="mesh" contype="0" conaffinity="0" group="1" density="0" rgba="0.89804 0.91765 0.92941 1" mesh="r_hip_calf_link"/>
              <geom size="0.03 0.03 0.105" pos="0 0 -0.06" type="box" rgba="0.89804 0.91765 0.92941 1"/>
              <body name="r_ankle_pitch_link" pos="0 0.00375 -0.19945">
                <inertial pos="0 0 0" quat="0.5 0.5 -0.5 0.5" mass="0.056538" diaginertia="6.3e-06 4.9e-06 4.7e-06"/>
                <joint name="r_ankle_pitch_joint" pos="0 0 0" axis="0 1 0" range="-0.90757 0.7854" actuatorfrcrange="-14.4 14.4"/>
                <geom type="mesh" contype="0" conaffinity="0" group="1" density="0" rgba="0.89804 0.91765 0.92941 1" mesh="r_ankle_pitch_link"/>
                <geom size="0.005 0.005 0.005" type="box" rgba="0.89804 0.91765 0.92941 1"/>
                <body name="r_ankle_roll_link">
                  <inertial pos="0.017291 -0.00079987 -0.030725" quat="0.0717589 0.724448 0.0777767 0.681158" mass="0.59911" diaginertia="0.00144003 0.00137984 0.000239531"/>
                  <joint name="r_ankle_roll_joint" pos="0 0 0" axis="1 0 0" range="-0.37525 0.37525" actuatorfrcrange="-14.4 14.4"/>
                  <geom type="mesh" contype="0" conaffinity="0" group="1" density="0" rgba="0.89804 0.91765 0.92941 1" mesh="r_ankle_roll_link"/>
                  <geom pos="-0.067 0.033 -0.044" quat="0.707388 0 0 -0.706825" type="mesh" rgba="0.89804 0.91765 0.92941 1" mesh="ankle_roll_simplify"/>
                </body>
              </body>
            </body>
          </body>
        </body>
      </body>
    </body>
  </worldbody>


  <actuator>
    <motor name="l_hip_pitch_joint" joint="l_hip_pitch_joint"/>
    <motor name="l_hip_roll_joint" joint="l_hip_roll_joint"/>
    <motor name="l_hip_thigh_joint" joint="l_hip_thigh_joint"/>
    <motor name="l_hip_calf_joint" joint="l_hip_calf_joint"/>
    <motor name="l_ankle_pitch_joint" joint="l_ankle_pitch_joint"/>
    <motor name="l_ankle_roll_joint" joint="l_ankle_roll_joint"/>
    
    <motor name="r_hip_pitch_joint" joint="r_hip_pitch_joint"/>
    <motor name="r_hip_roll_joint" joint="r_hip_roll_joint"/>
    <motor name="r_hip_thigh_joint" joint="r_hip_thigh_joint"/>
    <motor name="r_hip_calf_joint" joint="r_hip_calf_joint"/>
    <motor name="r_ankle_pitch_joint" joint="r_ankle_pitch_joint"/>
    <motor name="r_ankle_roll_joint" joint="r_ankle_roll_joint"/>
  </actuator>
</mujoco>